[2025-03-30T13:26:07.945+0000] {local_task_job_runner.py:123} INFO - ::group::Pre task execution logs
[2025-03-30T13:26:07.954+0000] {taskinstance.py:2614} INFO - Dependencies all met for dep_context=non-requeueable deps ti=<TaskInstance: my_dag.tsk_glue_job_trigger manual__2025-03-30T13:25:28.483218+00:00 [queued]>
[2025-03-30T13:26:07.959+0000] {taskinstance.py:2614} INFO - Dependencies all met for dep_context=requeueable deps ti=<TaskInstance: my_dag.tsk_glue_job_trigger manual__2025-03-30T13:25:28.483218+00:00 [queued]>
[2025-03-30T13:26:07.959+0000] {taskinstance.py:2867} INFO - Starting attempt 3 of 3
[2025-03-30T13:26:07.976+0000] {taskinstance.py:2890} INFO - Executing <Task(PythonOperator): tsk_glue_job_trigger> on 2025-03-30 13:25:28.483218+00:00
[2025-03-30T13:26:07.980+0000] {standard_task_runner.py:72} INFO - Started process 7030 to run task
[2025-03-30T13:26:07.983+0000] {standard_task_runner.py:104} INFO - Running: ['airflow', 'tasks', 'run', 'my_dag', 'tsk_glue_job_trigger', 'manual__2025-03-30T13:25:28.483218+00:00', '--job-id', '17', '--raw', '--subdir', 'DAGS_FOLDER/customer_churn_dag.py', '--cfg-path', '/tmp/tmpapepfjvh']
[2025-03-30T13:26:07.985+0000] {standard_task_runner.py:105} INFO - Job 17: Subtask tsk_glue_job_trigger
[2025-03-30T13:26:08.030+0000] {task_command.py:467} INFO - Running <TaskInstance: my_dag.tsk_glue_job_trigger manual__2025-03-30T13:25:28.483218+00:00 [running]> on host ip-172-31-16-96.ec2.internal
[2025-03-30T13:26:08.083+0000] {taskinstance.py:3134} INFO - Exporting env vars: AIRFLOW_CTX_DAG_EMAIL='myemaildomain.com' AIRFLOW_CTX_DAG_OWNER='airflow' AIRFLOW_CTX_DAG_ID='my_dag' AIRFLOW_CTX_TASK_ID='tsk_glue_job_trigger' AIRFLOW_CTX_EXECUTION_DATE='2025-03-30T13:25:28.483218+00:00' AIRFLOW_CTX_TRY_NUMBER='3' AIRFLOW_CTX_DAG_RUN_ID='manual__2025-03-30T13:25:28.483218+00:00'
[2025-03-30T13:26:08.084+0000] {taskinstance.py:732} INFO - ::endgroup::
[2025-03-30T13:26:08.101+0000] {base.py:84} INFO - Retrieving connection 'aws_s3_conn'
[2025-03-30T13:26:08.102+0000] {connection_wrapper.py:325} INFO - AWS Connection (conn_id='aws_s3_conn', conn_type='aws') credentials retrieved from login and password.
[2025-03-30T13:26:08.320+0000] {taskinstance.py:3313} ERROR - Task failed with exception
Traceback (most recent call last):
  File "/home/ubuntu/customer_churn_youtube_venv/lib/python3.12/site-packages/airflow/models/taskinstance.py", line 768, in _execute_task
    result = _execute_callable(context=context, **execute_callable_kwargs)
             ^^^^^^^^^^^^^^^^^^^^^^^^^^^^^^^^^^^^^^^^^^^^^^^^^^^^^^^^^^^^^
  File "/home/ubuntu/customer_churn_youtube_venv/lib/python3.12/site-packages/airflow/models/taskinstance.py", line 734, in _execute_callable
    return ExecutionCallableRunner(
           ^^^^^^^^^^^^^^^^^^^^^^^^
  File "/home/ubuntu/customer_churn_youtube_venv/lib/python3.12/site-packages/airflow/utils/operator_helpers.py", line 252, in run
    return self.func(*args, **kwargs)
           ^^^^^^^^^^^^^^^^^^^^^^^^^^
  File "/home/ubuntu/customer_churn_youtube_venv/lib/python3.12/site-packages/airflow/models/baseoperator.py", line 424, in wrapper
    return func(self, *args, **kwargs)
           ^^^^^^^^^^^^^^^^^^^^^^^^^^^
  File "/home/ubuntu/customer_churn_youtube_venv/lib/python3.12/site-packages/airflow/operators/python.py", line 238, in execute
    return_value = self.execute_callable()
                   ^^^^^^^^^^^^^^^^^^^^^^^
  File "/home/ubuntu/customer_churn_youtube_venv/lib/python3.12/site-packages/airflow/operators/python.py", line 256, in execute_callable
    return runner.run(*self.op_args, **self.op_kwargs)
           ^^^^^^^^^^^^^^^^^^^^^^^^^^^^^^^^^^^^^^^^^^^
  File "/home/ubuntu/customer_churn_youtube_venv/lib/python3.12/site-packages/airflow/utils/operator_helpers.py", line 252, in run
    return self.func(*args, **kwargs)
           ^^^^^^^^^^^^^^^^^^^^^^^^^^
  File "/home/ubuntu/airflow/dags/customer_churn_dag.py", line 16, in glue_job_s3_redshift_transfer
    client.start_job_run(
  File "/home/ubuntu/customer_churn_youtube_venv/lib/python3.12/site-packages/botocore/client.py", line 570, in _api_call
    return self._make_api_call(operation_name, kwargs)
           ^^^^^^^^^^^^^^^^^^^^^^^^^^^^^^^^^^^^^^^^^^^
  File "/home/ubuntu/customer_churn_youtube_venv/lib/python3.12/site-packages/botocore/context.py", line 124, in wrapper
    return func(*args, **kwargs)
           ^^^^^^^^^^^^^^^^^^^^^
  File "/home/ubuntu/customer_churn_youtube_venv/lib/python3.12/site-packages/botocore/client.py", line 1031, in _make_api_call
    raise error_class(parsed_response, operation_name)
botocore.errorfactory.ConcurrentRunsExceededException: An error occurred (ConcurrentRunsExceededException) when calling the StartJobRun operation: Concurrent runs exceeded.
[2025-03-30T13:26:08.326+0000] {taskinstance.py:1226} INFO - Marking task as FAILED. dag_id=my_dag, task_id=tsk_glue_job_trigger, run_id=manual__2025-03-30T13:25:28.483218+00:00, execution_date=20250330T132528, start_date=20250330T132607, end_date=20250330T132608
[2025-03-30T13:26:08.349+0000] {taskinstance.py:341} INFO - ::group::Post task execution logs
[2025-03-30T13:26:08.349+0000] {standard_task_runner.py:124} ERROR - Failed to execute job 17 for task tsk_glue_job_trigger (An error occurred (ConcurrentRunsExceededException) when calling the StartJobRun operation: Concurrent runs exceeded.; 7030)
Traceback (most recent call last):
  File "/home/ubuntu/customer_churn_youtube_venv/lib/python3.12/site-packages/airflow/task/task_runner/standard_task_runner.py", line 117, in _start_by_fork
    ret = args.func(args, dag=self.dag)
          ^^^^^^^^^^^^^^^^^^^^^^^^^^^^^
  File "/home/ubuntu/customer_churn_youtube_venv/lib/python3.12/site-packages/airflow/cli/cli_config.py", line 49, in command
    return func(*args, **kwargs)
           ^^^^^^^^^^^^^^^^^^^^^
  File "/home/ubuntu/customer_churn_youtube_venv/lib/python3.12/site-packages/airflow/utils/cli.py", line 116, in wrapper
    return f(*args, **kwargs)
           ^^^^^^^^^^^^^^^^^^
  File "/home/ubuntu/customer_churn_youtube_venv/lib/python3.12/site-packages/airflow/cli/commands/task_command.py", line 483, in task_run
    task_return_code = _run_task_by_selected_method(args, _dag, ti)
                       ^^^^^^^^^^^^^^^^^^^^^^^^^^^^^^^^^^^^^^^^^^^^
  File "/home/ubuntu/customer_churn_youtube_venv/lib/python3.12/site-packages/airflow/cli/commands/task_command.py", line 256, in _run_task_by_selected_method
    return _run_raw_task(args, ti)
           ^^^^^^^^^^^^^^^^^^^^^^^
  File "/home/ubuntu/customer_churn_youtube_venv/lib/python3.12/site-packages/airflow/cli/commands/task_command.py", line 341, in _run_raw_task
    return ti._run_raw_task(
           ^^^^^^^^^^^^^^^^^
  File "/home/ubuntu/customer_churn_youtube_venv/lib/python3.12/site-packages/airflow/utils/session.py", line 97, in wrapper
    return func(*args, session=session, **kwargs)
           ^^^^^^^^^^^^^^^^^^^^^^^^^^^^^^^^^^^^^^
  File "/home/ubuntu/customer_churn_youtube_venv/lib/python3.12/site-packages/airflow/models/taskinstance.py", line 3006, in _run_raw_task
    return _run_raw_task(
           ^^^^^^^^^^^^^^
  File "/home/ubuntu/customer_churn_youtube_venv/lib/python3.12/site-packages/airflow/models/taskinstance.py", line 274, in _run_raw_task
    TaskInstance._execute_task_with_callbacks(
  File "/home/ubuntu/customer_churn_youtube_venv/lib/python3.12/site-packages/airflow/models/taskinstance.py", line 3161, in _execute_task_with_callbacks
    result = self._execute_task(context, task_orig)
             ^^^^^^^^^^^^^^^^^^^^^^^^^^^^^^^^^^^^^^
  File "/home/ubuntu/customer_churn_youtube_venv/lib/python3.12/site-packages/airflow/models/taskinstance.py", line 3185, in _execute_task
    return _execute_task(self, context, task_orig)
           ^^^^^^^^^^^^^^^^^^^^^^^^^^^^^^^^^^^^^^^
  File "/home/ubuntu/customer_churn_youtube_venv/lib/python3.12/site-packages/airflow/models/taskinstance.py", line 768, in _execute_task
    result = _execute_callable(context=context, **execute_callable_kwargs)
             ^^^^^^^^^^^^^^^^^^^^^^^^^^^^^^^^^^^^^^^^^^^^^^^^^^^^^^^^^^^^^
  File "/home/ubuntu/customer_churn_youtube_venv/lib/python3.12/site-packages/airflow/models/taskinstance.py", line 734, in _execute_callable
    return ExecutionCallableRunner(
           ^^^^^^^^^^^^^^^^^^^^^^^^
  File "/home/ubuntu/customer_churn_youtube_venv/lib/python3.12/site-packages/airflow/utils/operator_helpers.py", line 252, in run
    return self.func(*args, **kwargs)
           ^^^^^^^^^^^^^^^^^^^^^^^^^^
  File "/home/ubuntu/customer_churn_youtube_venv/lib/python3.12/site-packages/airflow/models/baseoperator.py", line 424, in wrapper
    return func(self, *args, **kwargs)
           ^^^^^^^^^^^^^^^^^^^^^^^^^^^
  File "/home/ubuntu/customer_churn_youtube_venv/lib/python3.12/site-packages/airflow/operators/python.py", line 238, in execute
    return_value = self.execute_callable()
                   ^^^^^^^^^^^^^^^^^^^^^^^
  File "/home/ubuntu/customer_churn_youtube_venv/lib/python3.12/site-packages/airflow/operators/python.py", line 256, in execute_callable
    return runner.run(*self.op_args, **self.op_kwargs)
           ^^^^^^^^^^^^^^^^^^^^^^^^^^^^^^^^^^^^^^^^^^^
  File "/home/ubuntu/customer_churn_youtube_venv/lib/python3.12/site-packages/airflow/utils/operator_helpers.py", line 252, in run
    return self.func(*args, **kwargs)
           ^^^^^^^^^^^^^^^^^^^^^^^^^^
  File "/home/ubuntu/airflow/dags/customer_churn_dag.py", line 16, in glue_job_s3_redshift_transfer
    client.start_job_run(
  File "/home/ubuntu/customer_churn_youtube_venv/lib/python3.12/site-packages/botocore/client.py", line 570, in _api_call
    return self._make_api_call(operation_name, kwargs)
           ^^^^^^^^^^^^^^^^^^^^^^^^^^^^^^^^^^^^^^^^^^^
  File "/home/ubuntu/customer_churn_youtube_venv/lib/python3.12/site-packages/botocore/context.py", line 124, in wrapper
    return func(*args, **kwargs)
           ^^^^^^^^^^^^^^^^^^^^^
  File "/home/ubuntu/customer_churn_youtube_venv/lib/python3.12/site-packages/botocore/client.py", line 1031, in _make_api_call
    raise error_class(parsed_response, operation_name)
botocore.errorfactory.ConcurrentRunsExceededException: An error occurred (ConcurrentRunsExceededException) when calling the StartJobRun operation: Concurrent runs exceeded.
[2025-03-30T13:26:08.397+0000] {local_task_job_runner.py:266} INFO - Task exited with return code 1
[2025-03-30T13:26:08.414+0000] {taskinstance.py:3901} INFO - 0 downstream tasks scheduled from follow-on schedule check
[2025-03-30T13:26:08.423+0000] {local_task_job_runner.py:245} INFO - ::endgroup::
